Workbook

Sheet Planning
A1: EDUFOODS — Planning du projet
A2: Du lundi 28/09/2026 au vendredi 04/12/2026 (10 semaines, un jour ouvré par colonne). Cellules en bleu = à modifier (début, durée, avancement). Fin et statut se calculent seuls.
I3: S1 — 28/09 | N3: S2 — 05/10 | S3: S3 — 12/10 | X3: S4 — 19/10 | AC3: S5 — 26/10 | AH3: S6 — 02/11 | AM3: S7 — 09/11 | AR3: S8 — 16/11 | AW3: S9 — 23/11 | BB3: S10 — 30/11
A4: N° | B4: Tâche | C4: Contrainte n° | D4: Début | E4: Durée (j ouvrés) | F4: Fin | G4: Avancement | H4: Statut | I4: 46293 | J4: 46294 | K4: 46295 | L4: 46296 | M4: 46297 | N4: 46300 | O4: 46301 | P4: 46302 | Q4: 46303 | R4: 46304 | S4: 46307 | T4: 46308 | U4: 46309 | V4: 46310 | W4: 46311 | X4: 46314 | Y4: 46315 | Z4: 46316 | AA4: 46317 | AB4: 46318 | AC4: 46321 | AD4: 46322 | AE4: 46323 | AF4: 46324 | AG4: 46325 | AH4: 46328 | AI4: 46329 | AJ4: 46330 | AK4: 46331 | AL4: 46332 | AM4: 46335 | AN4: 46336 | AO4: 46337 | AP4: 46338 | AQ4: 46339 | AR4: 46342 | AS4: 46343 | AT4: 46344 | AU4: 46345 | AV4: 46346 | AW4: 46349 | AX4: 46350 | AY4: 46351 | AZ4: 46352 | BA4: 46353 | BB4: 46356 | BC4: 46357 | BD4: 46358 | BE4: 46359 | BF4: 46360
A5: 1 | B5: ANALYSE ET CADRAGE | D5: =MIN(D6:D12) -> 46293 | E5: =NETWORKDAYS(D5,F5,Paramètres!$A$5:$A$10) -> 8 | F5: =MAX(F6:F12) -> 46302 | G5: =SUMPRODUCT(E6:E12,G6:G12)/SUM(E6:E12) -> 0.53333333 | H5: =IF(G5=1,"Terminé",IF(G5>0,"En cours","À faire")) -> En cours
A6: 1.1 | B6: Rédaction du cahier des charges | C6: — | D6: 46293 | E6: 3 | F6: =WORKDAY(D6,E6-1,Paramètres!$A$5:$A$10) -> 46295 | G6: 1 | H6: =IF(G6=1,"Terminé",IF(G6>0,"En cours","À faire")) -> Terminé
A7: 1.2 | B7: Schéma d'architecture du SI | C7: 1 | D7: 46295 | E7: 2 | F7: =WORKDAY(D7,E7-1,Paramètres!$A$5:$A$10) -> 46296 | G7: 1 | H7: =IF(G7=1,"Terminé",IF(G7>0,"En cours","À faire")) -> Terminé
A8: 1.3 | B8: Schéma réseau | C8: 1 | D8: 46295 | E8: 2 | F8: =WORKDAY(D8,E8-1,Paramètres!$A$5:$A$10) -> 46296 | G8: 1 | H8: =IF(G8=1,"Terminé",IF(G8>0,"En cours","À faire")) -> Terminé
A9: 1.4 | B9: Planning du projet | C9: 14 | D9: 46296 | E9: 1 | F9: =WORKDAY(D9,E9-1,Paramètres!$A$5:$A$10) -> 46296 | G9: 1 | H9: =IF(G9=1,"Terminé",IF(G9>0,"En cours","À faire")) -> Terminé
A10: 1.5 | B10: Recensement des ressources numériques | C10: 2 | D10: 46296 | E10: 3 | F10: =WORKDAY(D10,E10-1,Paramètres!$A$5:$A$10) -> 46300 | G10: 0 | H10: =IF(G10=1,"Terminé",IF(G10>0,"En cours","À faire")) -> À faire
A11: 1.6 | B11: Choix techniques et justification | C11: — | D11: 46300 | E11: 3 | F11: =WORKDAY(D11,E11-1,Paramètres!$A$5:$A$10) -> 46302 | G11: 0 | H11: =IF(G11=1,"Terminé",IF(G11>0,"En cours","À faire")) -> À faire
A12: 1.7 | B12: Mise en place de l'outil de gestion de projet | C12: 14 | D12: 46300 | E12: 1 | F12: =WORKDAY(D12,E12-1,Paramètres!$A$5:$A$10) -> 46300 | G12: 0 | H12: =IF(G12=1,"Terminé",IF(G12>0,"En cours","À faire")) -> À faire
A13: 2 | B13: INFRASTRUCTURE | D13: =MIN(D14:D19) -> 46303 | E13: =NETWORKDAYS(D13,F13,Paramètres!$A$5:$A$10) -> 14 | F13: =MAX(F14:F19) -> 46322 | G13: =SUMPRODUCT(E14:E19,G14:G19)/SUM(E14:E19) -> 0 | H13: =IF(G13=1,"Terminé",IF(G13>0,"En cours","À faire")) -> À faire
A14: 2.1 | B14: Installation des serveurs / hyperviseur | C14: 1 | D14: 46303 | E14: 3 | F14: =WORKDAY(D14,E14-1,Paramètres!$A$5:$A$10) -> 46307 | G14: 0 | H14: =IF(G14=1,"Terminé",IF(G14>0,"En cours","À faire")) -> À faire
A15: 2.2 | B15: Configuration réseau (VLAN, routage) | C15: 1 | D15: 46307 | E15: 3 | F15: =WORKDAY(D15,E15-1,Paramètres!$A$5:$A$10) -> 46309 | G15: 0 | H15: =IF(G15=1,"Terminé",IF(G15>0,"En cours","À faire")) -> À faire
A16: 2.3 | B16: Configuration du pare-feu et de la DMZ | C16: 1, 9 | D16: 46309 | E16: 3 | F16: =WORKDAY(D16,E16-1,Paramètres!$A$5:$A$10) -> 46311 | G16: 0 | H16: =IF(G16=1,"Terminé",IF(G16>0,"En cours","À faire")) -> À faire
A17: 2.4 | B17: Annuaire, DNS, DHCP | C17: 6 | D17: 46314 | E17: 3 | F17: =WORKDAY(D17,E17-1,Paramètres!$A$5:$A$10) -> 46316 | G17: 0 | H17: =IF(G17=1,"Terminé",IF(G17>0,"En cours","À faire")) -> À faire
A18: 2.5 | B18: Comptes, groupes et droits d'accès | C18: 6 | D18: 46316 | E18: 2 | F18: =WORKDAY(D18,E18-1,Paramètres!$A$5:$A$10) -> 46317 | G18: 0 | H18: =IF(G18=1,"Terminé",IF(G18>0,"En cours","À faire")) -> À faire
A19: 2.6 | B19: Partage de fichiers | C19: 6 | D19: 46318 | E19: 3 | F19: =WORKDAY(D19,E19-1,Paramètres!$A$5:$A$10) -> 46322 | G19: 0 | H19: =IF(G19=1,"Terminé",IF(G19>0,"En cours","À faire")) -> À faire
A20: 3 | B20: SERVICES ET APPLICATION WEB | D20: =MIN(D21:D26) -> 46314 | E20: =NETWORKDAYS(D20,F20,Paramètres!$A$5:$A$10) -> 19 | F20: =MAX(F21:F26) -> 46339 | G20: =SUMPRODUCT(E21:E26,G21:G26)/SUM(E21:E26) -> 0 | H20: =IF(G20=1,"Terminé",IF(G20>0,"En cours","À faire")) -> À faire
A21: 3.1 | B21: Conception de la base de données | C21: 4 | D21: 46314 | E21: 3 | F21: =WORKDAY(D21,E21-1,Paramètres!$A$5:$A$10) -> 46316 | G21: 0 | H21: =IF(G21=1,"Terminé",IF(G21>0,"En cours","À faire")) -> À faire
A22: 3.2 | B22: Développement de l'application web (PWA) | C22: 4 | D22: 46317 | E22: 14 | F22: =WORKDAY(D22,E22-1,Paramètres!$A$5:$A$10) -> 46336 | G22: 0 | H22: =IF(G22=1,"Terminé",IF(G22>0,"En cours","À faire")) -> À faire
A23: 3.3 | B23: Site vitrine | C23: 3 | D23: 46321 | E23: 5 | F23: =WORKDAY(D23,E23-1,Paramètres!$A$5:$A$10) -> 46325 | G23: 0 | H23: =IF(G23=1,"Terminé",IF(G23>0,"En cours","À faire")) -> À faire
A24: 3.4 | B24: Outil de gestion des tickets (ITIL) | C24: 5, 10, 11, 12 | D24: 46328 | E24: 4 | F24: =WORKDAY(D24,E24-1,Paramètres!$A$5:$A$10) -> 46331 | G24: 0 | H24: =IF(G24=1,"Terminé",IF(G24>0,"En cours","À faire")) -> À faire
A25: 3.5 | B25: Catégories, priorités et procédures ITIL | C25: 5, 10, 11, 12 | D25: 46331 | E25: 2 | F25: =WORKDAY(D25,E25-1,Paramètres!$A$5:$A$10) -> 46332 | G25: 0 | H25: =IF(G25=1,"Terminé",IF(G25>0,"En cours","À faire")) -> À faire
A26: 3.6 | B26: Intégration Stripe et API cartographie | C26: 4 | D26: 46335 | E26: 4 | F26: =WORKDAY(D26,E26-1,Paramètres!$A$5:$A$10) -> 46339 | G26: 0 | H26: =IF(G26=1,"Terminé",IF(G26>0,"En cours","À faire")) -> À faire
A27: 4 | B27: SÉCURITÉ ET EXPLOITATION | D27: =MIN(D28:D32) -> 46336 | E27: =NETWORKDAYS(D27,F27,Paramètres!$A$5:$A$10) -> 8 | F27: =MAX(F28:F32) -> 46346 | G27: =SUMPRODUCT(E28:E32,G28:G32)/SUM(E28:E32) -> 0 | H27: =IF(G27=1,"Terminé",IF(G27>0,"En cours","À faire")) -> À faire
A28: 4.1 | B28: Charte d'utilisation et règles de sécurité | C28: 9 | D28: 46336 | E28: 2 | F28: =WORKDAY(D28,E28-1,Paramètres!$A$5:$A$10) -> 46338 | G28: 0 | H28: =IF(G28=1,"Terminé",IF(G28>0,"En cours","À faire")) -> À faire
A29: 4.2 | B29: Sauvegarde + test de restauration | C29: 8 | D29: 46338 | E29: 3 | F29: =WORKDAY(D29,E29-1,Paramètres!$A$5:$A$10) -> 46342 | G29: 0 | H29: =IF(G29=1,"Terminé",IF(G29>0,"En cours","À faire")) -> À faire
A30: 4.3 | B30: Continuité de service + test de reprise | C30: 7 | D30: 46342 | E30: 4 | F30: =WORKDAY(D30,E30-1,Paramètres!$A$5:$A$10) -> 46345 | G30: 0 | H30: =IF(G30=1,"Terminé",IF(G30>0,"En cours","À faire")) -> À faire
A31: 4.4 | B31: Supervision des serveurs et services | C31: 7, 11 | D31: 46342 | E31: 3 | F31: =WORKDAY(D31,E31-1,Paramètres!$A$5:$A$10) -> 46344 | G31: 0 | H31: =IF(G31=1,"Terminé",IF(G31>0,"En cours","À faire")) -> À faire
A32: 4.5 | B32: Analyse du trafic (indicateurs) | C32: 13 | D32: 46345 | E32: 2 | F32: =WORKDAY(D32,E32-1,Paramètres!$A$5:$A$10) -> 46346 | G32: 0 | H32: =IF(G32=1,"Terminé",IF(G32>0,"En cours","À faire")) -> À faire
A33: 5 | B33: TESTS ET MISE EN PRODUCTION | D33: =MIN(D34:D36) -> 46346 | E33: =NETWORKDAYS(D33,F33,Paramètres!$A$5:$A$10) -> 6 | F33: =MAX(F34:F36) -> 46353 | G33: =SUMPRODUCT(E34:E36,G34:G36)/SUM(E34:E36) -> 0 | H33: =IF(G33=1,"Terminé",IF(G33>0,"En cours","À faire")) -> À faire
A34: 5.1 | B34: Plan de tests et recette | C34: 16 | D34: 46346 | E34: 4 | F34: =WORKDAY(D34,E34-1,Paramètres!$A$5:$A$10) -> 46351 | G34: 0 | H34: =IF(G34=1,"Terminé",IF(G34>0,"En cours","À faire")) -> À faire
A35: 5.2 | B35: Mise en production | C35: 17 | D35: 46352 | E35: 2 | F35: =WORKDAY(D35,E35-1,Paramètres!$A$5:$A$10) -> 46353 | G35: 0 | H35: =IF(G35=1,"Terminé",IF(G35>0,"En cours","À faire")) -> À faire
A36: 5.3 | B36: Indicateurs de suivi du projet | C36: 15 | D36: 46352 | E36: 1 | F36: =WORKDAY(D36,E36-1,Paramètres!$A$5:$A$10) -> 46352 | G36: 0 | H36: =IF(G36=1,"Terminé",IF(G36>0,"En cours","À faire")) -> À faire
A37: 6 | B37: ACCOMPAGNEMENT ET CLÔTURE | D37: =MIN(D38:D40) -> 46353 | E37: =NETWORKDAYS(D37,F37,Paramètres!$A$5:$A$10) -> 6 | F37: =MAX(F38:F40) -> 46360 | G37: =SUMPRODUCT(E38:E40,G38:G40)/SUM(E38:E40) -> 0 | H37: =IF(G37=1,"Terminé",IF(G37>0,"En cours","À faire")) -> À faire
A38: 6.1 | B38: Supports et guides utilisateurs | C38: 18 | D38: 46353 | E38: 3 | F38: =WORKDAY(D38,E38-1,Paramètres!$A$5:$A$10) -> 46357 | G38: 0 | H38: =IF(G38=1,"Terminé",IF(G38>0,"En cours","À faire")) -> À faire
A39: 6.2 | B39: Documentation technique finale | C39: — | D39: 46356 | E39: 3 | F39: =WORKDAY(D39,E39-1,Paramètres!$A$5:$A$10) -> 46358 | G39: 0 | H39: =IF(G39=1,"Terminé",IF(G39>0,"En cours","À faire")) -> À faire
A40: 6.3 | B40: Préparation de la soutenance | C40: — | D40: 46358 | E40: 3 | F40: =WORKDAY(D40,E40-1,Paramètres!$A$5:$A$10) -> 46360 | G40: 0 | H40: =IF(G40=1,"Terminé",IF(G40>0,"En cours","À faire")) -> À faire
...

Sheet Indicateurs
A1: Indicateurs de suivi du projet
A3: Nombre total de tâches | B3: =SUMPRODUCT(--ISTEXT(Planning!$A$5:$A$40)) -> 30
A4: Tâches terminées | B4: =COUNTIFS(Planning!$A$5:$A$40,"*.*",Planning!$H$5:$H$40,"Terminé") -> 4
A5: Tâches en cours | B5: =COUNTIFS(Planning!$A$5:$A$40,"*.*",Planning!$H$5:$H$40,"En cours") -> 0
A6: Tâches à faire | B6: =COUNTIFS(Planning!$A$5:$A$40,"*.*",Planning!$H$5:$H$40,"À faire") -> 26
A7: Tâches en retard (fin dépassée, non terminées) | B7: =SUMPRODUCT(ISTEXT(Planning!$A$5:$A$40)*(Planning!$F$5:$F$40<TODAY())*(Planning!$G$5:$G$40<1)) -> 0
A8: Avancement global (pondéré par la durée) | B8: =SUMPRODUCT(ISTEXT(Planning!$A$5:$A$40)*Planning!$E$5:$E$40*Planning!$G$5:$G$40)/SUMPRODUCT(ISTEXT(Planning!$A$5:$A$40)*Planning!$E$5:$E$40) -> 0.085106383
A9: Date de fin prévue du projet | B9: =MAX(Planning!$F$5:$F$40) -> 46360
A10: Contraintes obligatoires couvertes | B10: 18 / 18

Sheet Paramètres
A1: Paramètres
A3: Jours fériés (exclus du calcul des jours ouvrés)
A4: Date | B4: Jour
A5: 46327 | B5: Toussaint
A6: 46337 | B6: Armistice
A7: 46381 | B7: Noël
